Workbook

Sheet deals
A1: deal_id | B1: rep_id | C1: stage | D1: sort_order | E1: deal_value | F1: lead_source | G1: region | H1: created_date | I1: closed_date
A2: D10001 | B2: R120 | C2: New Lead | D2: =_xlfn.XLOOKUP(C2, stage_mapping!$A$1:$A$8, stage_mapping!$B$1:$B$8) -> 1 | E2: 62605 | F2: Website | G2: Central | H2: 45588
A3: D10002 | B3: R118 | C3: Qualified | D3: =_xlfn.XLOOKUP(C3, stage_mapping!$A$1:$A$8, stage_mapping!$B$1:$B$8) -> 2 | E3: 40246 | F3: Linkedin | G3: East | H3: 45996
A4: D10003 | B4: R113 | C4: Qualified | D4: =_xlfn.XLOOKUP(C4, stage_mapping!$A$1:$A$8, stage_mapping!$B$1:$B$8) -> 2 | E4: 62608 | F4: Referral | G4: South | H4: 45561
A5: D10004 | B5: R114 | C5: Closed Lost | D5: =_xlfn.XLOOKUP(C5, stage_mapping!$A$1:$A$8, stage_mapping!$B$1:$B$8) -> 8 | E5: 29 | F5: Linkedin | G5: Midwest | H5: 45858 | I5: 45909
A6: D10005 | B6: R106 | C6: Qualified | D6: =_xlfn.XLOOKUP(C6, stage_mapping!$A$1:$A$8, stage_mapping!$B$1:$B$8) -> 2 | E6: 8840 | F6: Partner | G6: West | H6: 45915
A7: D10006 | B7: R108 | C7: New Lead | D7: =_xlfn.XLOOKUP(C7, stage_mapping!$A$1:$A$8, stage_mapping!$B$1:$B$8) -> 1 | E7: 3531 | F7: Webinar | G7: South | H7: 45362
A8: D10007 | B8: R110 | C8: Proposal | D8: =_xlfn.XLOOKUP(C8, stage_mapping!$A$1:$A$8, stage_mapping!$B$1:$B$8) -> 4 | E8: 21102 | F8: Email | G8: East | H8: 45415 | I8: 45490
A9: D10008 | B9: R103 | C9: Qualified | D9: =_xlfn.XLOOKUP(C9, stage_mapping!$A$1:$A$8, stage_mapping!$B$1:$B$8) -> 2 | E9: 18282 | F9: Email | G9: West | H9: 45876
A10: D10009 | B10: R102 | C10: New Lead | D10: =_xlfn.XLOOKUP(C10, stage_mapping!$A$1:$A$8, stage_mapping!$B$1:$B$8) -> 1 | E10: 14155 | F10: Partner | G10: Central | H10: 45841
A11: D10010 | B11: R106 | C11: Proposal | D11: =_xlfn.XLOOKUP(C11, stage_mapping!$A$1:$A$8, stage_mapping!$B$1:$B$8) -> 4 | E11: 5434 | F11: Referral | G11: West | H11: 45680
A12: D10011 | B12: R107 | C12: Proposal | D12: =_xlfn.XLOOKUP(C12, stage_mapping!$A$1:$A$8, stage_mapping!$B$1:$B$8) -> 4 | E12: 5449 | F12: Cold Call | G12: East | H12: 45350
A13: D10012 | B13: R119 | C13: New Lead | D13: =_xlfn.XLOOKUP(C13, stage_mapping!$A$1:$A$8, stage_mapping!$B$1:$B$8) -> 1 | E13: 18200 | F13: Website | G13: South | H13: 45870
A14: D10013 | B14: R101 | C14: New Lead | D14: =_xlfn.XLOOKUP(C14, stage_mapping!$A$1:$A$8, stage_mapping!$B$1:$B$8) -> 1 | E14: 6716 | F14: Webinar | G14: East | H14: 45563 | I14: 45599
A15: D10014 | B15: R101 | C15: Negotiating | D15: =_xlfn.XLOOKUP(C15, stage_mapping!$A$1:$A$8, stage_mapping!$B$1:$B$8) -> 6 | E15: 20453 | F15: Referral | G15: East | H15: 45429
A16: D10015 | B16: R103 | C16: Proposal | D16: =_xlfn.XLOOKUP(C16, stage_mapping!$A$1:$A$8, stage_mapping!$B$1:$B$8) -> 4 | E16: 8256 | F16: Website | G16: West | H16: 45560
A17: D10016 | B17: R114 | C17: Closed Lost | D17: =_xlfn.XLOOKUP(C17, stage_mapping!$A$1:$A$8, stage_mapping!$B$1:$B$8) -> 8 | E17: 23107 | F17: Linkedin | G17: Central | H17: 45332 | I17: 45398
A18: D10017 | B18: R106 | C18: Closed Won | D18: =_xlfn.XLOOKUP(C18, stage_mapping!$A$1:$A$8, stage_mapping!$B$1:$B$8) -> 7 | E18: 19913 | F18: Website | G18: West | H18: 45713 | I18: 45773
A19: D10018 | B19: R108 | C19: Proposal | D19: =_xlfn.XLOOKUP(C19, stage_mapping!$A$1:$A$8, stage_mapping!$B$1:$B$8) -> 4 | E19: 8315 | F19: Website | G19: South | H19: 45577
A20: D10019 | B20: R104 | C20: Proposal | D20: =_xlfn.XLOOKUP(C20, stage_mapping!$A$1:$A$8, stage_mapping!$B$1:$B$8) -> 4 | E20: 13805 | F20: Email | G20: East | H20: 45815
A21: D10020 | B21: R104 | C21: Negotiating | D21: =_xlfn.XLOOKUP(C21, stage_mapping!$A$1:$A$8, stage_mapping!$B$1:$B$8) -> 6 | E21: 11550 | F21: Cold Call | G21: East | H21: 46005
A22: D10021 | B22: R110 | C22: Proposal | D22: =_xlfn.XLOOKUP(C22, stage_mapping!$A$1:$A$8, stage_mapping!$B$1:$B$8) -> 4 | E22: 14340 | F22: Cold Call | G22: East | H22: 45983
A23: D10022 | B23: R110 | C23: New Lead | D23: =_xlfn.XLOOKUP(C23, stage_mapping!$A$1:$A$8, stage_mapping!$B$1:$B$8) -> 1 | E23: 23321 | F23: Website | G23: East | H23: 45917
A24: D10023 | B24: R114 | C24: New Lead | D24: =_xlfn.XLOOKUP(C24, stage_mapping!$A$1:$A$8, stage_mapping!$B$1:$B$8) -> 1 | E24: 8231 | F24: Cold Call | G24: Central | H24: 45416
A25: D10024 | B25: R118 | C25: Proposal | D25: =_xlfn.XLOOKUP(C25, stage_mapping!$A$1:$A$8, stage_mapping!$B$1:$B$8) -> 4 | E25: 51292 | F25: Email | G25: East | H25: 45545
A26: D10025 | B26: R105 | C26: Closed Won | D26: =_xlfn.XLOOKUP(C26, stage_mapping!$A$1:$A$8, stage_mapping!$B$1:$B$8) -> 7 | E26: 7753 | F26: Email | G26: East | H26: 45709 | I26: 45755
A27: D10026 | B27: R112 | C27: Closed Lost | D27: =_xlfn.XLOOKUP(C27, stage_mapping!$A$1:$A$8, stage_mapping!$B$1:$B$8) -> 8 | E27: 15447 | F27: Partner | G27: Midwest | H27: 45851 | I27: 45897
A28: D10027 | B28: R113 | C28: Negotiating | D28: =_xlfn.XLOOKUP(C28, stage_mapping!$A$1:$A$8, stage_mapping!$B$1:$B$8) -> 6 | E28: 18.4 | F28: Website | G28: West | H28: 45764
A29: D10028 | B29: R116 | C29: Closed Lost | D29: =_xlfn.XLOOKUP(C29, stage_mapping!$A$1:$A$8, stage_mapping!$B$1:$B$8) -> 8 | E29: 45099 | F29: Website | G29: Central | H29: 45362 | I29: 45435
A30: D10029 | B30: R115 | C30: Contract Review | D30: =_xlfn.XLOOKUP(C30, stage_mapping!$A$1:$A$8, stage_mapping!$B$1:$B$8) -> 5 | E30: 17838 | F30: Website | G30: South | H30: 45409
A31: D10030 | B31: R119 | C31: Closed Won | D31: =_xlfn.XLOOKUP(C31, stage_mapping!$A$1:$A$8, stage_mapping!$B$1:$B$8) -> 7 | E31: 16621 | F31: Referral | G31: South | H31: 45992 | I31: 46070
A32: D10031 | B32: R114 | C32: Qualified | D32: =_xlfn.XLOOKUP(C32, stage_mapping!$A$1:$A$8, stage_mapping!$B$1:$B$8) -> 2 | E32: 2837 | F32: Website | G32: South | H32: 45958
A33: D10032 | B33: R115 | C33: Negotiating | D33: =_xlfn.XLOOKUP(C33, stage_mapping!$A$1:$A$8, stage_mapping!$B$1:$B$8) -> 6 | E33: 17927 | F33: Cold Call | G33: South | H33: 45798
A34: D10033 | B34: R114 | C34: Negotiating | D34: =_xlfn.XLOOKUP(C34, stage_mapping!$A$1:$A$8, stage_mapping!$B$1:$B$8) -> 6 | E34: 6053 | F34: Email | G34: Central | H34: 45309
A35: D10034 | B35: R115 | C35: Closed Won | D35: =_xlfn.XLOOKUP(C35, stage_mapping!$A$1:$A$8, stage_mapping!$B$1:$B$8) -> 7 | E35: 3513 | F35: Referral | G35: South | H35: 45840 | I35: 45893
A36: D10035 | B36: R112 | C36: Qualified | D36: =_xlfn.XLOOKUP(C36, stage_mapping!$A$1:$A$8, stage_mapping!$B$1:$B$8) -> 2 | E36: 14015 | F36: Email | G36: Central | H36: 45347
A37: D10036 | B37: R109 | C37: Proposal | D37: =_xlfn.XLOOKUP(C37, stage_mapping!$A$1:$A$8, stage_mapping!$B$1:$B$8) -> 4 | E37: 52734 | F37: Partner | G37: South | H37: 45936
A38: D10037 | B38: R117 | C38: Negotiating | D38: =_xlfn.XLOOKUP(C38, stage_mapping!$A$1:$A$8, stage_mapping!$B$1:$B$8) -> 6 | E38: 30037 | F38: Referral | G38: East | H38: 45874
A39: D10038 | B39: R114 | C39: New Lead | D39: =_xlfn.XLOOKUP(C39, stage_mapping!$A$1:$A$8, stage_mapping!$B$1:$B$8) -> 1 | E39: 19.7 | F39: Linkedin | G39: Central | H39: 45581
A40: D10039 | B40: R105 | C40: Closed Won | D40: =_xlfn.XLOOKUP(C40, stage_mapping!$A$1:$A$8, stage_mapping!$B$1:$B$8) -> 7 | E40: 29496 | F40: Website | G40: West | H40: 45874 | I40: 45911
...

Sheet stage_mapping
A1: New Lead | B1: 1
A2: Qualified | B2: 2
A3: SQL | B3: 3
A4: Proposal | B4: 4
A5: Contract Review | B5: 5
A6: Negotiating | B6: 6
A7: Closed Won | B7: 7
A8: Closed Lost | B8: 8

Sheet sales_reps
A1: rep_id | B1: rep_name | C1: team | D1: region
A2: R101 | B2: Ava Patel | C2: SMB | D2: East
A3: R102 | B3: Marcus Chen | C3: SMB | D3: Central
A4: R103 | B4: Sofia Ramirez | C4: Mid-Market | D4: West
A5: R104 | B5: Ethan Brooks | C5: Mid-Market | D5: East
A6: R105 | B6: Priya Nair | C6: SMB | D6: East
A7: R106 | B7: Jordan Kim | C7: SMB | D7: West
A8: R107 | B8: Noah Thompson | C8: Mid-Market | D8: East
A9: R108 | B9: Isabella Garcia | C9: SMB | D9: South
A10: R109 | B10: Liam Johnson | C10: Enterprise | D10: Central
A11: R110 | B11: Maya Singh | C11: Enterprise | D11: East
A12: R111 | B12: Daniel Wright | C12: Mid-Market | D12: West
... A21: R120 | B21: Ella Rivera | C21: Enterprise | D21: Central
